terminate called after throwing an instance of 'std::range_error'
  what():  Data not found
FAIL src/bind/test-bind (exit status: 134)
